Workbook

Sheet Sheet1
B2: P1024 | C2: P0924 | D2: P0824 | E2: P0724 | F2: P0624 | G2: P0524 | H2: P0424 | I2: P0324 | J2: P0224 | K2: P0124 | L2: P1223 | M2: P1123 | N2: P1023 | O2: P0923 | P2: P0823 | Q2: P0723 | R2: P0623 | S2: P0523 | T2: P0423 | U2: P0323 | V2: P0223 | W2: P0123 | X2: P1222 | Y2: P1122 | Z2: P1022 | AA2: P0922 | AB2: P0822 | AC2: P0722 | AD2: P0622
A3: BORATE TREATED | B3: =AVERAGE('317421 - P1024'!H4:H9) -> -0.023584906 | C3: =AVERAGE('316556 - P0924'!H4:H9) -> 0.050832952 | D3: =AVERAGE('315805 - P0824'!H4:H9) -> -0.056069526 | E3: =AVERAGE('315019 - P0724'!H4:H9) -> -0.010852673 | F3: =AVERAGE('314020 - P0624'!H4:H9) -> -0.014164306 | G3: =AVERAGE('310785 - P0524'!H4:H9) -> -0.07967331 | H3: =AVERAGE('305245 - P0424'!H4:H9) -> 0.079149803 | I3: =AVERAGE('301055 - P0324'!H4:H9) -> -0.050432383 | J3: =AVERAGE('297195 - P0224'!H4:H9) -> 0.061523035 | K3: =AVERAGE('294130 - P0124'!H4:H9) -> 0.063770286 | L3: =AVERAGE('290710 - P1223'!H4:H9) -> -0.049487243 | M3: -0.038649959 | N3: -0.057091202 | O3: -0.023923445 | P3: -0.013315579 | Q3: -0.068158337 | R3: -0.0079759119 | S3: 0.0058667374 | T3: -0.04498261 | U3: 0.1366141 | V3: -0.090231939 | W3: -0.048874945 | X3: 0.031214323 | Y3: -0.06277692 | Z3: -0.073315098 | AA3: 0.01123625 | AB3: -0.0053965509 | AC3: -0.27035852 | AD3: -0.011340408
A4: CEDARTONE TRT | B4: =AVERAGE('317421 - P1024'!H10:H17) -> -0.033983172 | C4: =AVERAGE('316556 - P0924'!H10:H17) -> 0.062000495 | D4: =AVERAGE('315805 - P0824'!H10:H17) -> -0.059368375 | E4: =AVERAGE('315019 - P0724'!H10:H17) -> 0.0097106439 | F4: =AVERAGE('314020 - P0624'!H10:H17) -> -0.10262663 | G4: =AVERAGE('310785 - P0524'!H10:H17) -> -0.050933317 | H4: =AVERAGE('305245 - P0424'!H10:H17) -> -0.012397815 | I4: =AVERAGE('301055 - P0324'!H10:H17) -> -0.0050504917 | J4: =AVERAGE('297195 - P0224'!H10:H17) -> 0.030300728 | K4: =AVERAGE('294130 - P0124'!H10:H17) -> -0.028031043 | L4: =AVERAGE('290710 - P1223'!H10:H17) -> -0.056378686 | M4: -0.0048408097 | N4: -0.020497662 | O4: 0.030921373 | P4: 0.024909705 | Q4: -0.043069306 | R4: -0.018636232 | S4: -0.0051890042 | T4: 0.0005153424 | U4: 0.0080751501 | V4: -0.043512818 | W4: 0.010374587 | X4: 0.049023784 | Y4: -0.054623712 | Z4: -0.001026692 | AA4: 0.12522389 | AB4: -0.11886125 | AC4: -0.1172119 | AD4: -0.18442292
A5: STUDS | B5: =AVERAGE('317421 - P1024'!H27,'317421 - P1024'!H30) -> 0.10171213 | C5: =AVERAGE('316556 - P0924'!H27,'316556 - P0924'!H30) -> 0.019566411 | D5: =AVERAGE('315805 - P0824'!H27,'315805 - P0824'!H30) -> -0.061563398 | E5: =AVERAGE('315019 - P0724'!H27,'315019 - P0724'!H30) -> -0.032374412 | F5: =AVERAGE('314020 - P0624'!H27,'314020 - P0624'!H30) -> -0.11327692 | G5: =AVERAGE('310785 - P0524'!H27,'310785 - P0524'!H30) -> 0.012376238 | H5: =AVERAGE('305245 - P0424'!H27,'305245 - P0424'!H30) -> 0.084355297 | I5: =AVERAGE('301055 - P0324'!H27,'301055 - P0324'!H30) -> 0.0089527309 | J5: =AVERAGE('297195 - P0224'!H27,'297195 - P0224'!H30) -> 0.022893773 | K5: =AVERAGE('294130 - P0124'!H27,'294130 - P0124'!H30) -> 0.080356514 | L5: =AVERAGE('290710 - P1223'!H27,'290710 - P1223'!H30) -> -0.036904485 | M5: -0.10591746 | N5: 0.013202391 | O5: -0.12108087 | P5: 0.11757653 | Q5: -0.055478218 | R5: 0.0044404973 | S5: 0.043112649 | T5: -0.067774961 | U5: 0.20578199 | V5: -0.021336777 | W5: -0.17033673 | X5: -0.035029643 | Y5: -0.065710595 | Z5: -0.065160694 | AA5: 0.012768685 | AB5: 0.1045791 | AC5: -0.42898941 | AD5: 0.090461444
A6: 2X DIM | B6: =AVERAGE('317421 - P1024'!H34:H49) -> 0.044352044 | C6: =AVERAGE('316556 - P0924'!H34:H49) -> 0.071031746 | D6: =AVERAGE('315805 - P0824'!H34:H49) -> -0.040472518 | E6: =AVERAGE('315019 - P0724'!H34:H49) -> -0.034579298 | F6: =AVERAGE('314020 - P0624'!H34:H49) -> -0.11496296 | G6: =AVERAGE('310785 - P0524'!H34:H49) -> 0.023397257 | H6: =AVERAGE('305245 - P0424'!H34:H49) -> 0.071494728 | I6: =AVERAGE('301055 - P0324'!H34:H49) -> 0.0085144928 | J6: =AVERAGE('297195 - P0224'!H34:H49) -> 0.039823009 | K6: =AVERAGE('294130 - P0124'!H34:H49) -> 0.081562557 | L6: =AVERAGE('290710 - P1223'!H34:H49) -> -0.054121599 | M6: -0.063649425 | N6: -0.044584317 | O6: -0.049914196 | P6: 0.10267472 | Q6: -0.036881419 | R6: 0.017992817 | S6: 0.16017747 | T6: -0.17515152 | U6: 0.21153846 | V6: -0.095583787 | W6: -0.12549156 | X6: -0.021545525 | Y6: -0.032297332 | Z6: -0.064088022 | AA6: -0.026243332 | AB6: -0.0098072299 | AC6: -0.3949112 | AD6: -0.019615789
A7: WIDES | B7: =AVERAGE('317421 - P1024'!H72:H89) -> 0.18416319 | C7: =AVERAGE('316556 - P0924'!H72:H89) -> -0.017491973 | D7: =AVERAGE('315805 - P0824'!H72:H89) -> -0.0018408829 | E7: =AVERAGE('315019 - P0724'!H72:H89) -> -0.0047013688 | F7: =AVERAGE('314020 - P0624'!H72:H89) -> -0.040882992 | G7: =AVERAGE('310785 - P0524'!H72:H89) -> 0.041974343 | H7: =AVERAGE('305245 - P0424'!H72:H89) -> 0.027407008 | I7: =AVERAGE('301055 - P0324'!H72:H89) -> 0.032917644 | J7: =AVERAGE('297195 - P0224'!H72:H89) -> 0.25756842 | K7: =AVERAGE('294130 - P0124'!H72:H89) -> -0.32808159 | L7: =AVERAGE('290710 - P1223'!H72:H89) -> -0.046512009 | M7: -0.057395553 | N7: -0.024083666 | O7: -0.01161406 | P7: 0.19000246 | Q7: -0.070732409 | R7: -0.070765505 | S7: -0.058927092 | T7: -0.043561882 | U7: 0.02807052 | V7: -0.091690644 | W7: -0.078966596 | X7: 0.066063442 | Y7: 0.10092701 | Z7: -0.069013101 | AA7: -0.032292374 | AB7: -0.040453916 | AC7: -0.19691657 | AD7: 0.0057297002
A8: OSB | B8: =AVERAGE('317421 - P1024'!H93:H97) -> -0.0091346437 | C8: =AVERAGE('316556 - P0924'!H93:H97) -> -0.024919933 | D8: =AVERAGE('315805 - P0824'!H93:H97) -> -0.10430406 | E8: =AVERAGE('315019 - P0724'!H93:H97) -> -0.11253405 | F8: =AVERAGE('314020 - P0624'!H93:H97) -> -0.19077066 | G8: =AVERAGE('310785 - P0524'!H93:H97) -> 0.27694423 | H8: =AVERAGE('305245 - P0424'!H93:H97) -> 0.090021659 | I8: =AVERAGE('301055 - P0324'!H93:H97) -> -0.070619715 | J8: =AVERAGE('297195 - P0224'!H93:H97) -> 0 | K8: =AVERAGE('294130 - P0124'!H93:H97) -> 0.09396459 | L8: =AVERAGE('290710 - P1223'!H93:H97) -> 0.14096998 | M8: -0.31099556 | N8: -0.084227856 | O8: 0.089548437 | P8: 0.50711677 | Q8: 0 | R8: 0.19671337 | S8: -0.025077908 | T8: 0 | U8: 0.0092937174 | V8: -0.022156437 | W8: -0.16431281 | X8: 0.0015869062 | Y8: -0.058865434 | Z8: -0.21046149 | AA8: 0.14026922 | AB8: -0.20641417 | AC8: -0.31714688 | AD8: -0.23560876
A9: EWP | B9: ='317421 - P1024'!H116 -> 0 | C9: ='316556 - P0924'!H116 -> 0 | D9: ='315805 - P0824'!H116 -> 0 | E9: ='315019 - P0724'!H116 -> 0 | F9: ='314020 - P0624'!H116 -> 0 | G9: ='310785 - P0524'!H116 -> -0.034245351 | H9: ='305245 - P0424'!H116 -> 0 | I9: ='301055 - P0324'!H116 -> 0 | J9: ='297195 - P0224'!H116 -> 0 | K9: ='294130 - P0124'!H116 -> 0 | L9: ='290710 - P1223'!H116 -> 0 | M9: 0 | N9: 0.00031806616 | O9: 0.00031806616 | P9: 0 | Q9: 0 | R9: 0 | S9: 0.01555096 | T9: 0 | U9: 0 | V9: -0.067306877 | W9: -0.042956708 | X9: 0 | Y9: 0 | Z9: 0 | AA9: 0.010302234 | AB9: 0.0081663044 | AC9: 0 | AD9: 0
A10: HARDIE | AD10: 0.04
A11: TREX | AD11: 0.08
A13: SPF #2 | B13: =AVERAGE('317421 - P1024'!H416:H417) -> 0.081898585 | C13: =AVERAGE('316556 - P0924'!H416:H417) -> 0.1369724 | D13: =AVERAGE('315805 - P0824'!H416:H417) -> -0.075 | E13: =AVERAGE('315019 - P0724'!H416:H417) -> -0.020306154 | F13: =AVERAGE('314020 - P0624'!H416:H417) -> -0.10909993 | G13: =AVERAGE('310785 - P0524'!H416:H417) -> -0.032374134 | H13: =AVERAGE('305245 - P0424'!H416:H417) -> 0.074896744 | I13: =AVERAGE('301055 - P0324'!H416:H417) -> -0.021883552 | J13: =AVERAGE('297195 - P0224'!H416:H417) -> 0.090691998 | K13: =AVERAGE('294130 - P0124'!H416:H417) -> 0.018636556 | L13: =AVERAGE('290710 - P1223'!H416:H417) -> 0.046844284 | M13: -0.089893556 | N13: 0.038154639 | O13: -0.12436789 | P13: 0.14000865 | Q13: -0.026103447 | R13: 0.00071780148 | S13: -0.030893683 | T13: -0.15493043 | U13: 0.18416699 | V13: -0.030159161 | W13: -0.087832757 | X13: 0.030814 | Y13: -0.036072958 | Z13: -0.12942657 | AA13: -0.0012799822 | AB13: 0.1093044 | AC13: -0.4613604 | AD13: 0.043428088
A14: SPF 1650 | B14: ='317421 - P1024'!H418 -> 0.0327654 | C14: ='316556 - P0924'!H418 -> 0.013280212 | D14: ='315805 - P0824'!H418 -> -0.056390977 | E14: ='315019 - P0724'!H418 -> -0.024449878 | F14: ='314020 - P0624'!H418 -> -0.052143685 | G14: ='310785 - P0524'!H418 -> 0.0058275058 | H14: ='305245 - P0424'!H418 -> 0 | I14: ='301055 - P0324'!H418 -> -0.0057937428 | J14: ='297195 - P0224'!H418 -> 0.017688679 | K14: ='294130 - P0124'!H418 -> 0.0059311981 | L14: ='290710 - P1223'!H418 -> -0.050675676 | M14: -0.016611296 | N14: 0.011198208 | O14: 0.028801843 | P14: 0.016339869 | Q14: 0 | R14: 0.0064267352 | S14: -0.08254717 | T14: -0.023041475 | U14: 0.035799523 | V14: -0.11603376 | W14: -0.064165844 | X14: 0.025303644 | Y14: 0.010224949 | Z14: -0.048638132 | AA14: -0.04193849 | AB14: -0.0092336103 | AC14: -0.30931122 | AD14: -0.081967213
A16: PANEL | M16: -0.06 | O16: -0.03 | P16: 0.09 | Q16: -0.03 | R16: 0.03 | S16: 0.01 | T16: -0.04 | U16: 0.1 | V16: -0.04 | W16: -0.13 | X16: 0.005 | Y16: -0.05 | Z16: -0.1 | AA16: 0.04
A17: MULTI ROOF | J17: 0.01 | M17: -0.01 | O17: -0.01 | P17: 0.06 | Q17: 0 | R17: 0.01 | S17: -0.01 | T17: -0.045 | U17: 0.05 | V17: -0.03 | W17: -0.04 | X17: 0.015 | Y17: -0.01 | Z17: -0.06 | AA17: -0.01
A18: SFR ROOF | H18: 0.01 | J18: 0.01 | M18: -0.01 | O18: -0.02 | P18: 0.07 | R18: 0.02 | S18: -0.01 | T18: -0.045 | U18: 0.05 | V18: -0.03
A19: FLOOR TRUSSES | H19: 0.01 | J19: 0.01 | M19: -0.005 | O19: -0.02 | P19: 0.06 | R19: 0.02 | S19: -0.02

Sheet 317421 - P1024 (2)
E1: RANDOM LENGTH | F1: RANDOM LENGTH | I1: SELL PRICE | J1: SELL PRICE | M1: TYPE
B2: PROJECT | C2: SUPPLIER | D2: Product Code & Description | E2: 45513 | F2: 45765 | I2: P09 2024 SEPTEMBER 08/09/24 | J2: P10 2024 OCTOBER 09/13/24
A3: 1 | D3: Treated Materials | M3: COM
A4: 2 | C4: DH | D4: 2412BT - 2X4 12' Blue Borate Treated | E4: 706 | F4: 846 | G4: =+F4-E4 -> 140 | H4: =(F4-E4)/ABS(E4) -> 0.19830028 | I4: 851.61761 | J4: =(I4*H4)+I4 -> 1020.4936 | K4: =J4-I4 -> 168.87601 | L4: =(J4-I4)/ABS(I4) -> 0.19830028 | M4: COM | O4: =E4-'315805 - P0824'!F4 -> 35 | P4: =I4-'315805 - P0824'!J4 -> 42.219003
A5: 3 | D5: 2414BT - 2X4 14' Blue Borate Treated | E5: 706 | F5: =F4 -> 846 | G5: =+F5-E5 -> 140 | H5: =(F5-E5)/ABS(E5) -> 0.19830028 | I5: 851.61761 | J5: =(I5*H5)+I5 -> 1020.4936 | K5: =J5-I5 -> 168.87601 | L5: =(J5-I5)/ABS(I5) -> 0.19830028 | M5: COM | O5: =E5-'315805 - P0824'!F5 -> 35 | P5: =I5-'315805 - P0824'!J5 -> 42.219003
A6: 4 | D6: 2416BT - 2X4 16' Blue Borate Treated | E6: 706 | F6: =F4 -> 846 | G6: =+F6-E6 -> 140 | H6: =(F6-E6)/ABS(E6) -> 0.19830028 | I6: 851.61761 | J6: =(I6*H6)+I6 -> 1020.4936 | K6: =J6-I6 -> 168.87601 | L6: =(J6-I6)/ABS(I6) -> 0.19830028 | M6: COM | O6: =E6-'315805 - P0824'!F6 -> 35 | P6: =I6-'315805 - P0824'!J6 -> 42.219003
A7: 5 | C7: DH | D7: 2612BT - 2X6 12' Blue Borate Treated | E7: 636 | F7: 751 | G7: =+F7-E7 -> 115 | H7: =(F7-E7)/ABS(E7) -> 0.18081761 | I7: 820.97525 | J7: =(I7*H7)+I7 -> 969.42203 | K7: =J7-I7 -> 148.44678 | L7: =(J7-I7)/ABS(I7) -> 0.18081761 | M7: COM | O7: =E7-'315805 - P0824'!F7 -> 30 | P7: =I7-'315805 - P0824'!J7 -> 38.725248
A8: 6 | D8: 2614BT - 2X6 14' Blue Borate Treated | E8: 636 | F8: =F7 -> 751 | G8: =+F8-E8 -> 115 | H8: =(F8-E8)/ABS(E8) -> 0.18081761 | I8: 820.97525 | J8: =(I8*H8)+I8 -> 969.42203 | K8: =J8-I8 -> 148.44678 | L8: =(J8-I8)/ABS(I8) -> 0.18081761 | M8: COM | O8: =E8-'315805 - P0824'!F8 -> 30 | P8: =I8-'315805 - P0824'!J8 -> 38.725248
A9: 7 | D9: 2616BT - 2X6 16' Blue Borate Treated | E9: 636 | F9: =F7 -> 751 | G9: =+F9-E9 -> 115 | H9: =(F9-E9)/ABS(E9) -> 0.18081761 | I9: 820.97525 | J9: =(I9*H9)+I9 -> 969.42203 | K9: =J9-I9 -> 148.44678 | L9: =(J9-I9)/ABS(I9) -> 0.18081761 | M9: COM | O9: =E9-'315805 - P0824'!F9 -> 30 | P9: =I9-'315805 - P0824'!J9 -> 38.725248
A10: 8 | C10: DH | D10: 2412T - 2x4 12' #1 SYP Treated MCA Cedartone | E10: 825 | F10: 930 | G10: =+F10-E10 -> 105 | H10: =(F10-E10)/ABS(E10) -> 0.12727273 | I10: 1095.6822 | J10: =(I10*H10)+I10 -> 1235.1326 | K10: =J10-I10 -> 139.45046 | L10: =(J10-I10)/ABS(I10) -> 0.12727273 | M10: COM | O10: =E10-'315805 - P0824'!F10 -> 115 | P10: =I10-'315805 - P0824'!J10 -> 152.73146
A11: 9 | D11: 2416T - 2x4 16' #1 SYP Treated MCA Cedartone | E11: 825 | F11: =F10 -> 930 | G11: =+F11-E11 -> 105 | H11: =(F11-E11)/ABS(E11) -> 0.12727273 | I11: 1095.6822 | J11: =(I11*H11)+I11 -> 1235.1326 | K11: =J11-I11 -> 139.45046 | L11: =(J11-I11)/ABS(I11) -> 0.12727273 | M11: COM | O11: =E11-'315805 - P0824'!F11 -> 115 | P11: =I11-'315805 - P0824'!J11 -> 152.73146
A12: 10 | C12: DH | D12: 2612T - 2x6 12' #1 SYP Treated MCA Cedartone | E12: 710 | F12: 790 | G12: =+F12-E12 -> 80 | H12: =(F12-E12)/ABS(E12) -> 0.11267606 | I12: 846.92308 | J12: =(I12*H12)+I12 -> 942.35103 | K12: =J12-I12 -> 95.427952 | L12: =(J12-I12)/ABS(I12) -> 0.11267606 | M12: COM | O12: =E12-'315805 - P0824'!F12 -> 25 | P12: =I12-'315805 - P0824'!J12 -> 29.821235
A13: 11 | D13: 2616T - 2x6 16' #1 SYP Treated MCA Cedartone | E13: 710 | F13: =F12 -> 790 | G13: =+F13-E13 -> 80 | H13: =(F13-E13)/ABS(E13) -> 0.11267606 | I13: 846.92308 | J13: =(I13*H13)+I13 -> 942.35103 | K13: =J13-I13 -> 95.427952 | L13: =(J13-I13)/ABS(I13) -> 0.11267606 | M13: COM | O13: =E13-'315805 - P0824'!F13 -> 25 | P13: =I13-'315805 - P0824'!J13 -> 29.821235
A14: 12 | D14: 2812T - 2x8 12' #1 SYP Treated MCA Cedartone | E14: 680 | F14: 780 | G14: =+F14-E14 -> 100 | H14: =(F14-E14)/ABS(E14) -> 0.14705882 | I14: 874.08999 | J14: =(I14*H14)+I14 -> 1002.6326 | K14: =J14-I14 -> 128.54265 | L14: =(J14-I14)/ABS(I14) -> 0.14705882 | M14: COM | O14: =E14-'315805 - P0824'!F14 -> 20 | P14: =I14-'315805 - P0824'!J14 -> 25.708529
A15: 13 | D15: 2816T - 2x8 16' #1 SYP Treated MCA Cedartone | E15: 680 | F15: =F14 -> 780 | G15: =+F15-E15 -> 100 | H15: =(F15-E15)/ABS(E15) -> 0.14705882 | I15: 874.08999 | J15: =(I15*H15)+I15 -> 1002.6326 | K15: =J15-I15 -> 128.54265 | L15: =(J15-I15)/ABS(I15) -> 0.14705882 | M15: COM | O15: =E15-'315805 - P0824'!F15 -> 20 | P15: =I15-'315805 - P0824'!J15 -> 25.708529
A16: 14 | C16: DH | D16: 21012T - 2x10 12' #1 SYP Treated MCA Cedartone | E16: 795 | F16: 850 | G16: =+F16-E16 -> 55 | H16: =(F16-E16)/ABS(E16) -> 0.06918239 | I16: 1119.8387 | J16: =(I16*H16)+I16 -> 1197.3118 | K16: =J16-I16 -> 77.473118 | L16: =(J16-I16)/ABS(I16) -> 0.06918239 | M16: COM | O16: =E16-'315805 - P0824'!F16 -> 15 | P16: =I16-'315805 - P0824'!J16 -> 21.129032
A17: 15 | D17: 21016T - 2x10 16' #1 SYP Treated MCA Cedartone | E17: 795 | F17: =F16 -> 850 | G17: =+F17-E17 -> 55 | H17: =(F17-E17)/ABS(E17) -> 0.06918239 | I17: 1119.8387 | J17: =(I17*H17)+I17 -> 1197.3118 | K17: =J17-I17 -> 77.473118 | L17: =(J17-I17)/ABS(I17) -> 0.06918239 | M17: COM | O17: =E17-'315805 - P0824'!F17 -> 15 | P17: =I17-'315805 - P0824'!J17 -> 21.129032
A18: 16 | C18: DH | D18: 21212T - 2x12 12' #1 SYP Treated MCA Cedartone | E18: 880 | F18: 800 | G18: =+F18-E18 -> -80 | H18: =(F18-E18)/ABS(E18) -> -0.090909091 | I18: 1222.9958 | J18: =(I18*H18)+I18 -> 1111.8143 | K18: =J18-I18 -> -111.18143 | L18: =(J18-I18)/ABS(I18) -> -0.090909091 | M18: COM | O18: =E18-'315805 - P0824'!F18 -> 35 | P18: =I18-'315805 - P0824'!J18 -> 48.641878
A19: 17 | D19: 21216T - 2x12 16' #1 SYP Treated MCA Cedartone | E19: 880 | F19: =F18 -> 800 | G19: =+F19-E19 -> -80 | H19: =(F19-E19)/ABS(E19) -> -0.090909091 | I19: 1222.9958 | J19: =(I19*H19)+I19 -> 1111.8143 | K19: =J19-I19 -> -111.18143 | L19: =(J19-I19)/ABS(I19) -> -0.090909091 | M19: COM | O19: =E19-'315805 - P0824'!F19 -> 35 | P19: =I19-'315805 - P0824'!J19 -> 48.641878
A20: 18 | C20: DH | D20: 21220T - 2x12 20' #1 SYP Treated MCA Cedartone | E20: 1070 | F20: 1170 | G20: =+F20-E20 -> 100 | H20: =(F20-E20)/ABS(E20) -> 0.093457944 | I20: 2159.8757 | J20: =(I20*H20)+I20 -> 2361.7333 | K20: =J20-I20 -> 201.85755 | L20: =(J20-I20)/ABS(I20) -> 0.093457944 | M20: COM | O20: =E20-'315805 - P0824'!F20 -> 30 | P20: =I20-'315805 - P0824'!J20 -> 60.557264
A21: 19 | C21: DH | D21: 4410T - 4X4 10' HF Std/btr S4S CEDARTONE GROUND CONTACT | E21: 16.07 | F21: 17.2 | G21: =+F21-E21 -> 1.13 | H21: =(F21-E21)/ABS(E21) -> 0.070317362 | I21: 36.488665 | J21: =(I21*H21)+I21 -> 39.054452 | K21: =J21-I21 -> 2.5657867 | L21: =(J21-I21)/ABS(I21) -> 0.070317362 | M21: COM | O21: =E21-'315805 - P0824'!F21 -> 0 | P21: =I21-'315805 - P0824'!J21 -> 0
A22: 20 | C22: DH | D22: 6610T - 6X6 10' HF #2 S4S CEDARTONE GROUND CONTACT | E22: 1430 | F22: 1470 | G22: =+F22-E22 -> 40 | H22: =(F22-E22)/ABS(E22) -> 0.027972028 | I22: 2041.9222 | J22: =(I22*H22)+I22 -> 2099.0389 | K22: =J22-I22 -> 57.116705 | L22: =(J22-I22)/ABS(I22) -> 0.027972028 | M22: COM | O22: =E22-'315805 - P0824'!F22 -> 0 | P22: =I22-'315805 - P0824'!J22 -> 0
A23: 21 | D23: 6612T - 6X6 12' HF #2 S4S CEDARTONE GROUND CONTACT | E23: 1430 | F23: =F22 -> 1470 | G23: =+F23-E23 -> 40 | H23: =(F23-E23)/ABS(E23) -> 0.027972028 | I23: 2041.9222 | J23: =(I23*H23)+I23 -> 2099.0389 | K23: =J23-I23 -> 57.116705 | L23: =(J23-I23)/ABS(I23) -> 0.027972028 | M23: COM | O23: =E23-'315805 - P0824'!F23 -> 0 | P23: =I23-'315805 - P0824'!J23 -> 0
A24: 22 | D24: End of Treated Materials | H24: =AVERAGE(H4:H23) -> 0.10438174 | L24: =AVERAGE(L4:L23) -> 0.10438174
A25: 23 | D25: Studs | M25: COM
A26: 24 | D26: 2492F - 2X4 92-5/8 HEM FIR STUD | E26: 441 | F26: 544 | G26: =+F26-E26 -> 103 | H26: =(F26-E26)/ABS(E26) -> 0.23356009 | I26: 654.29675 | J26: 587 | K26: =J26-I26 -> -67.296754 | L26: =(J26-I26)/ABS(I26) -> -0.10285356 | M26: COM | O26: =E26-'315805 - P0824'!F26 -> 0 | P26: =I26-'315805 - P0824'!J26 -> 0
A27: 25 | D27: 24104F - 2X4 104-5/8 HEM FIR STUD | E27: 476 | F27: 632 | G27: =+F27-E27 -> 156 | H27: =(F27-E27)/ABS(E27) -> 0.32773109 | I27: 627.94534 | J27: 682 | K27: =J27-I27 -> 54.054664 | L27: =(J27-I27)/ABS(I27) -> 0.086081799 | M27: COM | O27: =E27-'315805 - P0824'!F27 -> 5 | P27: =I27-'315805 - P0824'!J27 -> 6.5960645
A28: 26 | D28: 24116F - 2X4 116-5/8 HEM FIR STUD | E28: 476 | F28: 635 | G28: =+F28-E28 -> 159 | H28: =(F28-E28)/ABS(E28) -> 0.33403361 | I28: 589.74688 | J28: 686 | K28: =J28-I28 -> 96.253119 | L28: =(J28-I28)/ABS(I28) -> 0.1632109 | M28: COM | O28: =E28-'315805 - P0824'!F28 -> 5 | P28: =I28-'315805 - P0824'!J28 -> 6.1948202
A29: 27 | D29: 2692F - 2X6 92-5/8 HEM FIR STUD | E29: 436 | F29: 596 | G29: =+F29-E29 -> 160 | H29: =(F29-E29)/ABS(E29) -> 0.36697248 | I29: 560.47438 | J29: 644 | K29: =J29-I29 -> 83.525623 | L29: =(J29-I29)/ABS(I29) -> 0.14902666 | M29: COM | O29: =E29-'315805 - P0824'!F29 -> 5 | P29: =I29-'315805 - P0824'!J29 -> 6.4274584
A30: 28 | D30: 26104F - 2X6 104-5/8 HEM FIR STUD | E30: 541 | F30: 686 | G30: =+F30-E30 -> 145 | H30: =(F30-E30)/ABS(E30) -> 0.26802218 | I30: 684.64138 | J30: 740 | K30: =J30-I30 -> 55.35862 | L30: =(J30-I30)/ABS(I30) -> 0.080857835 | M30: COM | O30: =E30-'315805 - P0824'!F30 -> 15 | P30: =I30-'315805 - P0824'!J30 -> 18.982663
A31: 29 | D31: 26116F - 2X6 116-5/8 HEM FIR STUD | E31: 541 | F31: 686 | G31: =+F31-E31 -> 145 | H31: =(F31-E31)/ABS(E31) -> 0.26802218 | I31: 646.77631 | J31: 741 | K31: =J31-I31 -> 94.223689 | L31: =(J31-I31)/ABS(I31) -> 0.14568203 | M31: COM | O31: =E31-'315805 - P0824'!F31 -> 15 | P31: =I31-'315805 - P0824'!J31 -> 17.9328
A32: 30 | D32: End of Studs | H32: =AVERAGE(H26:H31) -> 0.29972361 | L32: =AVERAGE(L26:L31) -> 0.087000944
A33: 31 | D33: Dimensional Lumber | M33: COM
A34: 32 | D34: 248F - 2X4X8 #2 AND BTR HEM FIR | E34: 555 | F34: 696 | G34: =+F34-E34 -> 141 | H34: =(F34-E34)/ABS(E34) -> 0.25405405 | I34: 631.07328 | J34: 765 | K34: =J34-I34 -> 133.92672 | L34: =(J34-I34)/ABS(I34) -> 0.21222056 | M34: COM | O34: =E34-'315805 - P0824'!F34 -> 15 | P34: =I34-'315805 - P0824'!J34 -> 17.056034
A35: 33 | D35: 2410F - 2X4X10 #2 AND BTR HEM FIR | E35: 555 | F35: =F34 -> 696 | G35: =+F35-E35 -> 141 | H35: =(F35-E35)/ABS(E35) -> 0.25405405 | I35: 631.07328 | J35: =J34 -> 765 | K35: =J35-I35 -> 133.92672 | L35: =(J35-I35)/ABS(I35) -> 0.21222056 | M35: COM | O35: =E35-'315805 - P0824'!F35 -> 15 | P35: =I35-'315805 - P0824'!J35 -> 17.056034
A36: 34 | D36: 2412F - 2X4X12 #2 AND BTR HEM FIR | E36: 555 | F36: =F34 -> 696 | G36: =+F36-E36 -> 141 | H36: =(F36-E36)/ABS(E36) -> 0.25405405 | I36: 631.07328 | J36: =J34 -> 765 | K36: =J36-I36 -> 133.92672 | L36: =(J36-I36)/ABS(I36) -> 0.21222056 | M36: COM | O36: =E36-'315805 - P0824'!F36 -> 15 | P36: =I36-'315805 - P0824'!J36 -> 17.056034
A37: 35 | D37: 2414F - 2X4X14 #2 AND BTR HEM FIR | E37: 555 | F37: =F34 -> 696 | G37: =+F37-E37 -> 141 | H37: =(F37-E37)/ABS(E37) -> 0.25405405 | I37: 631.07328 | J37: =J34 -> 765 | K37: =J37-I37 -> 133.92672 | L37: =(J37-I37)/ABS(I37) -> 0.21222056 | M37: COM | O37: =E37-'315805 - P0824'!F37 -> 15 | P37: =I37-'315805 - P0824'!J37 -> 17.056034
A38: 36 | D38: 2416F - 2X4X16 #2 AND BTR HEM FIR | E38: 555 | F38: =F34 -> 696 | G38: =+F38-E38 -> 141 | H38: =(F38-E38)/ABS(E38) -> 0.25405405 | I38: 631.07328 | J38: =J34 -> 765 | K38: =J38-I38 -> 133.92672 | L38: =(J38-I38)/ABS(I38) -> 0.21222056 | M38: COM | O38: =E38-'315805 - P0824'!F38 -> 15 | P38: =I38-'315805 - P0824'!J38 -> 17.056034
A39: 37 | D39: 2418F - 2X4X18 #2 AND BTR HEM FIR | E39: 555 | F39: =F34 -> 696 | G39: =+F39-E39 -> 141 | H39: =(F39-E39)/ABS(E39) -> 0.25405405 | I39: 631.07328 | J39: =J34 -> 765 | K39: =J39-I39 -> 133.92672 | L39: =(J39-I39)/ABS(I39) -> 0.21222056 | M39: COM | O39: =E39-'315805 - P0824'!F39 -> 15 | P39: =I39-'315805 - P0824'!J39 -> 17.056034
A40: 38 | D40: 2420F - 2X4X20 #2 AND BTR HEM FIR | E40: 555 | F40: =F34 -> 696 | G40: =+F40-E40 -> 141 | H40: =(F40-E40)/ABS(E40) -> 0.25405405 | I40: 631.07328 | J40: =J34 -> 765 | K40: =J40-I40 -> 133.92672 | L40: =(J40-I40)/ABS(I40) -> 0.21222056 | M40: COM | O40: =E40-'315805 - P0824'!F40 -> 15 | P40: =I40-'315805 - P0824'!J40 -> 17.056034
...

Sheet 317421 - P1024
E1: RANDOM LENGTH | F1: RANDOM LENGTH | I1: SELL PRICE | J1: SELL PRICE | M1: TYPE
B2: PROJECT | C2: SUPPLIER | D2: Product Code & Description | E2: P09 2024 SEPTEMBER 08/09/24 | F2: P10 2024 OCTOBER 09/13/24 | I2: P09 2024 SEPTEMBER 08/09/24 | J2: P10 2024 OCTOBER 09/13/24
A3: 1 | D3: Treated Materials | M3: COM
A4: 2 | C4: DH | D4: 2412BT - 2X4 12' Blue Borate Treated | E4: 706 | F4: 706 | G4: =+F4-E4 -> 0 | H4: =(F4-E4)/ABS(E4) -> 0 | I4: 851.61761 | J4: 852 | K4: =J4-I4 -> 0.38238702 | L4: =(J4-I4)/ABS(I4) -> 0.00044901258 | M4: COM | O4: =E4-'315805 - P0824'!F4 -> 35 | P4: =I4-'315805 - P0824'!J4 -> 42.219003
A5: 3 | D5: 2414BT - 2X4 14' Blue Borate Treated | E5: 706 | F5: =F4 -> 706 | G5: =+F5-E5 -> 0 | H5: =(F5-E5)/ABS(E5) -> 0 | I5: 851.61761 | J5: 852 | K5: =J5-I5 -> 0.38238702 | L5: =(J5-I5)/ABS(I5) -> 0.00044901258 | M5: COM | O5: =E5-'315805 - P0824'!F5 -> 35 | P5: =I5-'315805 - P0824'!J5 -> 42.219003
A6: 4 | D6: 2416BT - 2X4 16' Blue Borate Treated | E6: 706 | F6: =F4 -> 706 | G6: =+F6-E6 -> 0 | H6: =(F6-E6)/ABS(E6) -> 0 | I6: 851.61761 | J6: 852 | K6: =J6-I6 -> 0.38238702 | L6: =(J6-I6)/ABS(I6) -> 0.00044901258 | M6: COM | O6: =E6-'315805 - P0824'!F6 -> 35 | P6: =I6-'315805 - P0824'!J6 -> 42.219003
A7: 5 | C7: DH | D7: 2612BT - 2X6 12' Blue Borate Treated | E7: 636 | F7: 606 | G7: =+F7-E7 -> -30 | H7: =(F7-E7)/ABS(E7) -> -0.047169811 | I7: 820.97525 | J7: 821 | K7: =J7-I7 -> 0.024752475 | L7: =(J7-I7)/ABS(I7) -> 3.0150087e-05 | M7: COM | O7: =E7-'315805 - P0824'!F7 -> 30 | P7: =I7-'315805 - P0824'!J7 -> 38.725248
A8: 6 | D8: 2614BT - 2X6 14' Blue Borate Treated | E8: 636 | F8: =F7 -> 606 | G8: =+F8-E8 -> -30 | H8: =(F8-E8)/ABS(E8) -> -0.047169811 | I8: 820.97525 | J8: 821 | K8: =J8-I8 -> 0.024752475 | L8: =(J8-I8)/ABS(I8) -> 3.0150087e-05 | M8: COM | O8: =E8-'315805 - P0824'!F8 -> 30 | P8: =I8-'315805 - P0824'!J8 -> 38.725248
A9: 7 | D9: 2616BT - 2X6 16' Blue Borate Treated | E9: 636 | F9: =F7 -> 606 | G9: =+F9-E9 -> -30 | H9: =(F9-E9)/ABS(E9) -> -0.047169811 | I9: 820.97525 | J9: 821 | K9: =J9-I9 -> 0.024752475 | L9: =(J9-I9)/ABS(I9) -> 3.0150087e-05 | M9: COM | O9: =E9-'315805 - P0824'!F9 -> 30 | P9: =I9-'315805 - P0824'!J9 -> 38.725248
A10: 8 | C10: DH | D10: 2412T - 2x4 12' #1 SYP Treated MCA Cedartone | E10: 825 | F10: 825 | G10: =+F10-E10 -> 0 | H10: =(F10-E10)/ABS(E10) -> 0 | I10: 1095.6822 | J10: 1096 | K10: =J10-I10 -> 0.31781267 | L10: =(J10-I10)/ABS(I10) -> 0.00029005917 | M10: COM | O10: =E10-'315805 - P0824'!F10 -> 115 | P10: =I10-'315805 - P0824'!J10 -> 152.73146
A11: 9 | D11: 2416T - 2x4 16' #1 SYP Treated MCA Cedartone | E11: 825 | F11: =F10 -> 825 | G11: =+F11-E11 -> 0 | H11: =(F11-E11)/ABS(E11) -> 0 | I11: 1095.6822 | J11: 1096 | K11: =J11-I11 -> 0.31781267 | L11: =(J11-I11)/ABS(I11) -> 0.00029005917 | M11: COM | O11: =E11-'315805 - P0824'!F11 -> 115 | P11: =I11-'315805 - P0824'!J11 -> 152.73146
A12: 10 | C12: DH | D12: 2612T - 2x6 12' #1 SYP Treated MCA Cedartone | E12: 710 | F12: 685 | G12: =+F12-E12 -> -25 | H12: =(F12-E12)/ABS(E12) -> -0.035211268 | I12: 846.92308 | J12: 847 | K12: =J12-I12 -> 0.076923077 | L12: =(J12-I12)/ABS(I12) -> 9.0826521e-05 | M12: COM | O12: =E12-'315805 - P0824'!F12 -> 25 | P12: =I12-'315805 - P0824'!J12 -> 29.821235
A13: 11 | D13: 2616T - 2x6 16' #1 SYP Treated MCA Cedartone | E13: 710 | F13: =F12 -> 685 | G13: =+F13-E13 -> -25 | H13: =(F13-E13)/ABS(E13) -> -0.035211268 | I13: 846.92308 | J13: 847 | K13: =J13-I13 -> 0.076923077 | L13: =(J13-I13)/ABS(I13) -> 9.0826521e-05 | M13: COM | O13: =E13-'315805 - P0824'!F13 -> 25 | P13: =I13-'315805 - P0824'!J13 -> 29.821235
A14: 12 | D14: 2812T - 2x8 12' #1 SYP Treated MCA Cedartone | E14: 680 | F14: 650 | G14: =+F14-E14 -> -30 | H14: =(F14-E14)/ABS(E14) -> -0.044117647 | I14: 874.08999 | J14: 875 | K14: =J14-I14 -> 0.91000672 | L14: =(J14-I14)/ABS(I14) -> 0.0010410904 | M14: COM | O14: =E14-'315805 - P0824'!F14 -> 20 | P14: =I14-'315805 - P0824'!J14 -> 25.708529
A15: 13 | D15: 2816T - 2x8 16' #1 SYP Treated MCA Cedartone | E15: 680 | F15: =F14 -> 650 | G15: =+F15-E15 -> -30 | H15: =(F15-E15)/ABS(E15) -> -0.044117647 | I15: 874.08999 | J15: 875 | K15: =J15-I15 -> 0.91000672 | L15: =(J15-I15)/ABS(I15) -> 0.0010410904 | M15: COM | O15: =E15-'315805 - P0824'!F15 -> 20 | P15: =I15-'315805 - P0824'!J15 -> 25.708529
A16: 14 | C16: DH | D16: 21012T - 2x10 12' #1 SYP Treated MCA Cedartone | E16: 795 | F16: 750 | G16: =+F16-E16 -> -45 | H16: =(F16-E16)/ABS(E16) -> -0.056603774 | I16: 1119.8387 | J16: 1120 | K16: =J16-I16 -> 0.16129032 | L16: =(J16-I16)/ABS(I16) -> 0.00014402996 | M16: COM | O16: =E16-'315805 - P0824'!F16 -> 15 | P16: =I16-'315805 - P0824'!J16 -> 21.129032
A17: 15 | D17: 21016T - 2x10 16' #1 SYP Treated MCA Cedartone | E17: 795 | F17: =F16 -> 750 | G17: =+F17-E17 -> -45 | H17: =(F17-E17)/ABS(E17) -> -0.056603774 | I17: 1119.8387 | J17: 1120 | K17: =J17-I17 -> 0.16129032 | L17: =(J17-I17)/ABS(I17) -> 0.00014402996 | M17: COM | O17: =E17-'315805 - P0824'!F17 -> 15 | P17: =I17-'315805 - P0824'!J17 -> 21.129032
A18: 16 | C18: DH | D18: 21212T - 2x12 12' #1 SYP Treated MCA Cedartone | E18: 880 | F18: 920 | G18: =+F18-E18 -> 40 | H18: =(F18-E18)/ABS(E18) -> 0.045454545 | I18: 1222.9958 | J18: 1224 | K18: =J18-I18 -> 1.0042194 | L18: =(J18-I18)/ABS(I18) -> 0.00082111437 | M18: COM | O18: =E18-'315805 - P0824'!F18 -> 35 | P18: =I18-'315805 - P0824'!J18 -> 48.641878
A19: 17 | D19: 21216T - 2x12 16' #1 SYP Treated MCA Cedartone | E19: 880 | F19: =F18 -> 920 | G19: =+F19-E19 -> 40 | H19: =(F19-E19)/ABS(E19) -> 0.045454545 | I19: 1222.9958 | J19: 1224 | K19: =J19-I19 -> 1.0042194 | L19: =(J19-I19)/ABS(I19) -> 0.00082111437 | M19: COM | O19: =E19-'315805 - P0824'!F19 -> 35 | P19: =I19-'315805 - P0824'!J19 -> 48.641878
A20: 18 | C20: DH | D20: 21220T - 2x12 20' #1 SYP Treated MCA Cedartone | E20: 1070 | F20: 1120 | G20: =+F20-E20 -> 50 | H20: =(F20-E20)/ABS(E20) -> 0.046728972 | I20: 2159.8757 | J20: 2160 | K20: =J20-I20 -> 0.12425858 | L20: =(J20-I20)/ABS(I20) -> 5.7530429e-05 | M20: COM | O20: =E20-'315805 - P0824'!F20 -> 30 | P20: =I20-'315805 - P0824'!J20 -> 60.557264
A21: 19 | C21: DH | D21: 4410T - 4X4 10' HF Std/btr S4S CEDARTONE GROUND CONTACT | E21: 16.07 | F21: 16.07 | G21: =+F21-E21 -> 0 | H21: =(F21-E21)/ABS(E21) -> 0 | I21: 36.488665 | J21: 37 | K21: =J21-I21 -> 0.51133487 | L21: =(J21-I21)/ABS(I21) -> 0.014013526 | M21: COM | O21: =E21-'315805 - P0824'!F21 -> 0 | P21: =I21-'315805 - P0824'!J21 -> 0
A22: 20 | C22: DH | D22: 6610T - 6X6 10' HF #2 S4S CEDARTONE GROUND CONTACT | E22: 1430 | F22: 1430 | G22: =+F22-E22 -> 0 | H22: =(F22-E22)/ABS(E22) -> 0 | I22: 2041.9222 | J22: 2042 | K22: =J22-I22 -> 0.077803204 | L22: =(J22-I22)/ABS(I22) -> 3.8102923e-05 | M22: COM | O22: =E22-'315805 - P0824'!F22 -> 0 | P22: =I22-'315805 - P0824'!J22 -> 0
A23: 21 | D23: 6612T - 6X6 12' HF #2 S4S CEDARTONE GROUND CONTACT | E23: 1430 | F23: =F22 -> 1430 | G23: =+F23-E23 -> 0 | H23: =(F23-E23)/ABS(E23) -> 0 | I23: 2041.9222 | J23: 2042 | K23: =J23-I23 -> 0.077803204 | L23: =(J23-I23)/ABS(I23) -> 3.8102923e-05 | M23: COM | O23: =E23-'315805 - P0824'!F23 -> 0 | P23: =I23-'315805 - P0824'!J23 -> 0
A24: 22 | D24: End of Treated Materials | H24: =AVERAGE(H4:H23) -> -0.013786837 | L24: =AVERAGE(L4:L23) -> 0.0010179496
A25: 23 | D25: Studs | M25: COM
A26: 24 | D26: 2492F - 2X4 92-5/8 HEM FIR STUD | E26: 441 | F26: 475 | G26: =+F26-E26 -> 34 | H26: =(F26-E26)/ABS(E26) -> 0.077097506 | I26: 654.29675 | J26: 655 | K26: =J26-I26 -> 0.70324646 | L26: =(J26-I26)/ABS(I26) -> 0.0010748127 | M26: COM | O26: =E26-'315805 - P0824'!F26 -> 0 | P26: =I26-'315805 - P0824'!J26 -> 0
A27: 25 | D27: 24104F - 2X4 104-5/8 HEM FIR STUD | E27: 476 | F27: 513 | G27: =+F27-E27 -> 37 | H27: =(F27-E27)/ABS(E27) -> 0.077731092 | I27: 627.94534 | J27: 628 | K27: =J27-I27 -> 0.05466429 | L27: =(J27-I27)/ABS(I27) -> 8.7052625e-05 | M27: COM | O27: =E27-'315805 - P0824'!F27 -> 5 | P27: =I27-'315805 - P0824'!J27 -> 6.5960645
A28: 26 | D28: 24116F - 2X4 116-5/8 HEM FIR STUD | E28: 476 | F28: 513 | G28: =+F28-E28 -> 37 | H28: =(F28-E28)/ABS(E28) -> 0.077731092 | I28: 589.74688 | J28: 590 | K28: =J28-I28 -> 0.25311943 | L28: =(J28-I28)/ABS(I28) -> 0.00042920012 | M28: COM | O28: =E28-'315805 - P0824'!F28 -> 5 | P28: =I28-'315805 - P0824'!J28 -> 6.1948202
A29: 27 | D29: 2692F - 2X6 92-5/8 HEM FIR STUD | E29: 436 | F29: 476 | G29: =+F29-E29 -> 40 | H29: =(F29-E29)/ABS(E29) -> 0.091743119 | I29: 560.47438 | J29: 561 | K29: =J29-I29 -> 0.52562327 | L29: =(J29-I29)/ABS(I29) -> 0.00093781855 | M29: COM | O29: =E29-'315805 - P0824'!F29 -> 5 | P29: =I29-'315805 - P0824'!J29 -> 6.4274584
A30: 28 | D30: 26104F - 2X6 104-5/8 HEM FIR STUD | E30: 541 | F30: 609 | G30: =+F30-E30 -> 68 | H30: =(F30-E30)/ABS(E30) -> 0.12569316 | I30: 684.64138 | J30: 685 | K30: =J30-I30 -> 0.35861979 | L30: =(J30-I30)/ABS(I30) -> 0.00052380676 | M30: COM | O30: =E30-'315805 - P0824'!F30 -> 15 | P30: =I30-'315805 - P0824'!J30 -> 18.982663
A31: 29 | D31: 26116F - 2X6 116-5/8 HEM FIR STUD | E31: 541 | F31: 609 | G31: =+F31-E31 -> 68 | H31: =(F31-E31)/ABS(E31) -> 0.12569316 | I31: 646.77631 | J31: 647 | K31: =J31-I31 -> 0.22368865 | L31: =(J31-I31)/ABS(I31) -> 0.00034585164 | M31: COM | O31: =E31-'315805 - P0824'!F31 -> 15 | P31: =I31-'315805 - P0824'!J31 -> 17.9328
A32: 30 | D32: End of Studs | H32: =AVERAGE(H26:H31) -> 0.095948189 | L32: =AVERAGE(L26:L31) -> 0.00056642373
A33: 31 | D33: Dimensional Lumber | M33: COM
A34: 32 | D34: 248F - 2X4X8 #2 AND BTR HEM FIR | E34: 555 | F34: 590 | G34: =+F34-E34 -> 35 | H34: =(F34-E34)/ABS(E34) -> 0.063063063 | I34: 631.07328 | J34: 632 | K34: =J34-I34 -> 0.92672414 | L34: =(J34-I34)/ABS(I34) -> 0.001468489 | M34: COM | O34: =E34-'315805 - P0824'!F34 -> 15 | P34: =I34-'315805 - P0824'!J34 -> 17.056034
A35: 33 | D35: 2410F - 2X4X10 #2 AND BTR HEM FIR | E35: 555 | F35: =F34 -> 590 | G35: =+F35-E35 -> 35 | H35: =(F35-E35)/ABS(E35) -> 0.063063063 | I35: 631.07328 | J35: 632 | K35: =J35-I35 -> 0.92672414 | L35: =(J35-I35)/ABS(I35) -> 0.001468489 | M35: COM | O35: =E35-'315805 - P0824'!F35 -> 15 | P35: =I35-'315805 - P0824'!J35 -> 17.056034
A36: 34 | D36: 2412F - 2X4X12 #2 AND BTR HEM FIR | E36: 555 | F36: =F34 -> 590 | G36: =+F36-E36 -> 35 | H36: =(F36-E36)/ABS(E36) -> 0.063063063 | I36: 631.07328 | J36: 632 | K36: =J36-I36 -> 0.92672414 | L36: =(J36-I36)/ABS(I36) -> 0.001468489 | M36: COM | O36: =E36-'315805 - P0824'!F36 -> 15 | P36: =I36-'315805 - P0824'!J36 -> 17.056034
A37: 35 | D37: 2414F - 2X4X14 #2 AND BTR HEM FIR | E37: 555 | F37: =F34 -> 590 | G37: =+F37-E37 -> 35 | H37: =(F37-E37)/ABS(E37) -> 0.063063063 | I37: 631.07328 | J37: 632 | K37: =J37-I37 -> 0.92672414 | L37: =(J37-I37)/ABS(I37) -> 0.001468489 | M37: COM | O37: =E37-'315805 - P0824'!F37 -> 15 | P37: =I37-'315805 - P0824'!J37 -> 17.056034
A38: 36 | D38: 2416F - 2X4X16 #2 AND BTR HEM FIR | E38: 555 | F38: =F34 -> 590 | G38: =+F38-E38 -> 35 | H38: =(F38-E38)/ABS(E38) -> 0.063063063 | I38: 631.07328 | J38: 632 | K38: =J38-I38 -> 0.92672414 | L38: =(J38-I38)/ABS(I38) -> 0.001468489 | M38: COM | O38: =E38-'315805 - P0824'!F38 -> 15 | P38: =I38-'315805 - P0824'!J38 -> 17.056034
A39: 37 | D39: 2418F - 2X4X18 #2 AND BTR HEM FIR | E39: 555 | F39: =F34 -> 590 | G39: =+F39-E39 -> 35 | H39: =(F39-E39)/ABS(E39) -> 0.063063063 | I39: 631.07328 | J39: 632 | K39: =J39-I39 -> 0.92672414 | L39: =(J39-I39)/ABS(I39) -> 0.001468489 | M39: COM | O39: =E39-'315805 - P0824'!F39 -> 15 | P39: =I39-'315805 - P0824'!J39 -> 17.056034
A40: 38 | D40: 2420F - 2X4X20 #2 AND BTR HEM FIR | E40: 555 | F40: =F34 -> 590 | G40: =+F40-E40 -> 35 | H40: =(F40-E40)/ABS(E40) -> 0.063063063 | I40: 631.07328 | J40: 632 | K40: =J40-I40 -> 0.92672414 | L40: =(J40-I40)/ABS(I40) -> 0.001468489 | M40: COM | O40: =E40-'315805 - P0824'!F40 -> 15 | P40: =I40-'315805 - P0824'!J40 -> 17.056034
...

Sheet 316556 - P0924
E1: RANDOM LENGTH | F1: RANDOM LENGTH | I1: SELL PRICE | J1: SELL PRICE | M1: TYPE
B2: PROJECT | C2: SUPPLIER | D2: Product Code & Description | E2: P08 2024 AUGUST 07/12/24 | F2: P09 2024 SEPTEMBER 08/09/24 | I2: P08 2024 AUGUST 07/12/24 | J2: P09 2024 SEPTEMBER 08/09/24
A3: 1 | D3: Treated Materials | M3: COM
A4: 2 | C4: DH | D4: 2412BT - 2X4 12' Blue Borate Treated | E4: 671 | F4: 706 | G4: =+F4-E4 -> 35 | H4: =(F4-E4)/ABS(E4) -> 0.052160954 | I4: 809.39861 | J4: =(I4*H4)+I4 -> 851.61761 | K4: =J4-I4 -> 42.219003 | L4: =(J4-I4)/ABS(I4) -> 0.052160954 | M4: COM | O4: =E4-'315805 - P0824'!F4 -> 0 | P4: =I4-'315805 - P0824'!J4 -> 0
A5: 3 | D5: 2414BT - 2X4 14' Blue Borate Treated | E5: 671 | F5: =F4 -> 706 | G5: =+F5-E5 -> 35 | H5: =(F5-E5)/ABS(E5) -> 0.052160954 | I5: 809.39861 | J5: =(I5*H5)+I5 -> 851.61761 | K5: =J5-I5 -> 42.219003 | L5: =(J5-I5)/ABS(I5) -> 0.052160954 | M5: COM | O5: =E5-'315805 - P0824'!F5 -> 0 | P5: =I5-'315805 - P0824'!J5 -> 0
A6: 4 | D6: 2416BT - 2X4 16' Blue Borate Treated | E6: 671 | F6: =F4 -> 706 | G6: =+F6-E6 -> 35 | H6: =(F6-E6)/ABS(E6) -> 0.052160954 | I6: 809.39861 | J6: =(I6*H6)+I6 -> 851.61761 | K6: =J6-I6 -> 42.219003 | L6: =(J6-I6)/ABS(I6) -> 0.052160954 | M6: COM | O6: =E6-'315805 - P0824'!F6 -> 0 | P6: =I6-'315805 - P0824'!J6 -> 0
A7: 5 | C7: DH | D7: 2612BT - 2X6 12' Blue Borate Treated | E7: 606 | F7: 636 | G7: =+F7-E7 -> 30 | H7: =(F7-E7)/ABS(E7) -> 0.04950495 | I7: 782.25 | J7: =(I7*H7)+I7 -> 820.97525 | K7: =J7-I7 -> 38.725248 | L7: =(J7-I7)/ABS(I7) -> 0.04950495 | M7: COM | O7: =E7-'315805 - P0824'!F7 -> 0 | P7: =I7-'315805 - P0824'!J7 -> 0
A8: 6 | D8: 2614BT - 2X6 14' Blue Borate Treated | E8: 606 | F8: =F7 -> 636 | G8: =+F8-E8 -> 30 | H8: =(F8-E8)/ABS(E8) -> 0.04950495 | I8: 782.25 | J8: =(I8*H8)+I8 -> 820.97525 | K8: =J8-I8 -> 38.725248 | L8: =(J8-I8)/ABS(I8) -> 0.04950495 | M8: COM | O8: =E8-'315805 - P0824'!F8 -> 0 | P8: =I8-'315805 - P0824'!J8 -> 0
A9: 7 | D9: 2616BT - 2X6 16' Blue Borate Treated | E9: 606 | F9: =F7 -> 636 | G9: =+F9-E9 -> 30 | H9: =(F9-E9)/ABS(E9) -> 0.04950495 | I9: 782.25 | J9: =(I9*H9)+I9 -> 820.97525 | K9: =J9-I9 -> 38.725248 | L9: =(J9-I9)/ABS(I9) -> 0.04950495 | M9: COM | O9: =E9-'315805 - P0824'!F9 -> 0 | P9: =I9-'315805 - P0824'!J9 -> 0
A10: 8 | C10: DH | D10: 2412T - 2x4 12' #1 SYP Treated MCA Cedartone | E10: 710 | F10: 825 | G10: =+F10-E10 -> 115 | H10: =(F10-E10)/ABS(E10) -> 0.16197183 | I10: 942.95073 | J10: =(I10*H10)+I10 -> 1095.6822 | K10: =J10-I10 -> 152.73146 | L10: =(J10-I10)/ABS(I10) -> 0.16197183 | M10: COM | O10: =E10-'315805 - P0824'!F10 -> 0 | P10: =I10-'315805 - P0824'!J10 -> 0
A11: 9 | D11: 2416T - 2x4 16' #1 SYP Treated MCA Cedartone | E11: 710 | F11: =F10 -> 825 | G11: =+F11-E11 -> 115 | H11: =(F11-E11)/ABS(E11) -> 0.16197183 | I11: 942.95073 | J11: =(I11*H11)+I11 -> 1095.6822 | K11: =J11-I11 -> 152.73146 | L11: =(J11-I11)/ABS(I11) -> 0.16197183 | M11: COM | O11: =E11-'315805 - P0824'!F11 -> 0 | P11: =I11-'315805 - P0824'!J11 -> 0
A12: 10 | C12: DH | D12: 2612T - 2x6 12' #1 SYP Treated MCA Cedartone | E12: 685 | F12: 710 | G12: =+F12-E12 -> 25 | H12: =(F12-E12)/ABS(E12) -> 0.03649635 | I12: 817.10184 | J12: =(I12*H12)+I12 -> 846.92308 | K12: =J12-I12 -> 29.821235 | L12: =(J12-I12)/ABS(I12) -> 0.03649635 | M12: COM | O12: =E12-'315805 - P0824'!F12 -> 0 | P12: =I12-'315805 - P0824'!J12 -> 0
A13: 11 | D13: 2616T - 2x6 16' #1 SYP Treated MCA Cedartone | E13: 685 | F13: =F12 -> 710 | G13: =+F13-E13 -> 25 | H13: =(F13-E13)/ABS(E13) -> 0.03649635 | I13: 817.10184 | J13: =(I13*H13)+I13 -> 846.92308 | K13: =J13-I13 -> 29.821235 | L13: =(J13-I13)/ABS(I13) -> 0.03649635 | M13: COM | O13: =E13-'315805 - P0824'!F13 -> 0 | P13: =I13-'315805 - P0824'!J13 -> 0
A14: 12 | D14: 2812T - 2x8 12' #1 SYP Treated MCA Cedartone | E14: 660 | F14: 680 | G14: =+F14-E14 -> 20 | H14: =(F14-E14)/ABS(E14) -> 0.03030303 | I14: 848.38146 | J14: =(I14*H14)+I14 -> 874.08999 | K14: =J14-I14 -> 25.708529 | L14: =(J14-I14)/ABS(I14) -> 0.03030303 | M14: COM | O14: =E14-'315805 - P0824'!F14 -> 0 | P14: =I14-'315805 - P0824'!J14 -> 0
A15: 13 | D15: 2816T - 2x8 16' #1 SYP Treated MCA Cedartone | E15: 660 | F15: =F14 -> 680 | G15: =+F15-E15 -> 20 | H15: =(F15-E15)/ABS(E15) -> 0.03030303 | I15: 848.38146 | J15: =(I15*H15)+I15 -> 874.08999 | K15: =J15-I15 -> 25.708529 | L15: =(J15-I15)/ABS(I15) -> 0.03030303 | M15: COM | O15: =E15-'315805 - P0824'!F15 -> 0 | P15: =I15-'315805 - P0824'!J15 -> 0
A16: 14 | C16: DH | D16: 21012T - 2x10 12' #1 SYP Treated MCA Cedartone | E16: 780 | F16: 795 | G16: =+F16-E16 -> 15 | H16: =(F16-E16)/ABS(E16) -> 0.019230769 | I16: 1098.7097 | J16: =(I16*H16)+I16 -> 1119.8387 | K16: =J16-I16 -> 21.129032 | L16: =(J16-I16)/ABS(I16) -> 0.019230769 | M16: COM | O16: =E16-'315805 - P0824'!F16 -> 0 | P16: =I16-'315805 - P0824'!J16 -> 0
A17: 15 | D17: 21016T - 2x10 16' #1 SYP Treated MCA Cedartone | E17: 780 | F17: =F16 -> 795 | G17: =+F17-E17 -> 15 | H17: =(F17-E17)/ABS(E17) -> 0.019230769 | I17: 1098.7097 | J17: =(I17*H17)+I17 -> 1119.8387 | K17: =J17-I17 -> 21.129032 | L17: =(J17-I17)/ABS(I17) -> 0.019230769 | M17: COM | O17: =E17-'315805 - P0824'!F17 -> 0 | P17: =I17-'315805 - P0824'!J17 -> 0
A18: 16 | C18: DH | D18: 21212T - 2x12 12' #1 SYP Treated MCA Cedartone | E18: 845 | F18: 880 | G18: =+F18-E18 -> 35 | H18: =(F18-E18)/ABS(E18) -> 0.041420118 | I18: 1174.3539 | J18: =(I18*H18)+I18 -> 1222.9958 | K18: =J18-I18 -> 48.641878 | L18: =(J18-I18)/ABS(I18) -> 0.041420118 | M18: COM | O18: =E18-'315805 - P0824'!F18 -> 0 | P18: =I18-'315805 - P0824'!J18 -> 0
A19: 17 | D19: 21216T - 2x12 16' #1 SYP Treated MCA Cedartone | E19: 845 | F19: =F18 -> 880 | G19: =+F19-E19 -> 35 | H19: =(F19-E19)/ABS(E19) -> 0.041420118 | I19: 1174.3539 | J19: =(I19*H19)+I19 -> 1222.9958 | K19: =J19-I19 -> 48.641878 | L19: =(J19-I19)/ABS(I19) -> 0.041420118 | M19: COM | O19: =E19-'315805 - P0824'!F19 -> 0 | P19: =I19-'315805 - P0824'!J19 -> 0
A20: 18 | C20: DH | D20: 21220T - 2x12 20' #1 SYP Treated MCA Cedartone | E20: 1040 | F20: 1070 | G20: =+F20-E20 -> 30 | H20: =(F20-E20)/ABS(E20) -> 0.028846154 | I20: 2099.3185 | J20: =(I20*H20)+I20 -> 2159.8757 | K20: =J20-I20 -> 60.557264 | L20: =(J20-I20)/ABS(I20) -> 0.028846154 | M20: COM | O20: =E20-'315805 - P0824'!F20 -> 0 | P20: =I20-'315805 - P0824'!J20 -> 0
A21: 19 | C21: DH | D21: 4410T - 4X4 10' HF Std/btr S4S CEDARTONE GROUND CONTACT | E21: 16.07 | F21: 16.07 | G21: =+F21-E21 -> 0 | H21: =(F21-E21)/ABS(E21) -> 0 | I21: 36.488665 | J21: =(I21*H21)+I21 -> 36.488665 | K21: =J21-I21 -> 0 | L21: =(J21-I21)/ABS(I21) -> 0 | M21: COM | O21: =E21-'315805 - P0824'!F21 -> 0 | P21: =I21-'315805 - P0824'!J21 -> 0
A22: 20 | C22: DH | D22: 6610T - 6X6 10' HF #2 S4S CEDARTONE GROUND CONTACT | E22: 1430 | F22: 1430 | G22: =+F22-E22 -> 0 | H22: =(F22-E22)/ABS(E22) -> 0 | I22: 2041.9222 | J22: =(I22*H22)+I22 -> 2041.9222 | K22: =J22-I22 -> 0 | L22: =(J22-I22)/ABS(I22) -> 0 | M22: COM | O22: =E22-'315805 - P0824'!F22 -> 0 | P22: =I22-'315805 - P0824'!J22 -> 0
A23: 21 | D23: 6612T - 6X6 12' HF #2 S4S CEDARTONE GROUND CONTACT | E23: 1430 | F23: =F22 -> 1430 | G23: =+F23-E23 -> 0 | H23: =(F23-E23)/ABS(E23) -> 0 | I23: 2041.9222 | J23: =(I23*H23)+I23 -> 2041.9222 | K23: =J23-I23 -> 0 | L23: =(J23-I23)/ABS(I23) -> 0 | M23: COM | O23: =E23-'315805 - P0824'!F23 -> 0 | P23: =I23-'315805 - P0824'!J23 -> 0
A24: 22 | D24: End of Treated Materials | H24: =AVERAGE(H4:H23) -> 0.045634403 | L24: =AVERAGE(L4:L23) -> 0.045634403
A25: 23 | D25: Studs | M25: COM
A26: 24 | D26: 2492F - 2X4 92-5/8 HEM FIR STUD | E26: 441 | F26: 441 | G26: =+F26-E26 -> 0 | H26: =(F26-E26)/ABS(E26) -> 0 | I26: 654.29675 | J26: =(I26*H26)+I26 -> 654.29675 | K26: =J26-I26 -> 0 | L26: =(J26-I26)/ABS(I26) -> 0 | M26: COM | O26: =E26-'315805 - P0824'!F26 -> 0 | P26: =I26-'315805 - P0824'!J26 -> 0
A27: 25 | D27: 24104F - 2X4 104-5/8 HEM FIR STUD | E27: 471 | F27: 476 | G27: =+F27-E27 -> 5 | H27: =(F27-E27)/ABS(E27) -> 0.010615711 | I27: 621.34927 | J27: =(I27*H27)+I27 -> 627.94534 | K27: =J27-I27 -> 6.5960645 | L27: =(J27-I27)/ABS(I27) -> 0.010615711 | M27: COM | O27: =E27-'315805 - P0824'!F27 -> 0 | P27: =I27-'315805 - P0824'!J27 -> 0
A28: 26 | D28: 24116F - 2X4 116-5/8 HEM FIR STUD | E28: 471 | F28: 476 | G28: =+F28-E28 -> 5 | H28: =(F28-E28)/ABS(E28) -> 0.010615711 | I28: 583.55206 | J28: =(I28*H28)+I28 -> 589.74688 | K28: =J28-I28 -> 6.1948202 | L28: =(J28-I28)/ABS(I28) -> 0.010615711 | M28: COM | O28: =E28-'315805 - P0824'!F28 -> 0 | P28: =I28-'315805 - P0824'!J28 -> 0
A29: 27 | D29: 2692F - 2X6 92-5/8 HEM FIR STUD | E29: 431 | F29: 436 | G29: =+F29-E29 -> 5 | H29: =(F29-E29)/ABS(E29) -> 0.011600928 | I29: 554.04692 | J29: =(I29*H29)+I29 -> 560.47438 | K29: =J29-I29 -> 6.4274584 | L29: =(J29-I29)/ABS(I29) -> 0.011600928 | M29: COM | O29: =E29-'315805 - P0824'!F29 -> 0 | P29: =I29-'315805 - P0824'!J29 -> 0
A30: 28 | D30: 26104F - 2X6 104-5/8 HEM FIR STUD | E30: 526 | F30: 541 | G30: =+F30-E30 -> 15 | H30: =(F30-E30)/ABS(E30) -> 0.02851711 | I30: 665.65872 | J30: =(I30*H30)+I30 -> 684.64138 | K30: =J30-I30 -> 18.982663 | L30: =(J30-I30)/ABS(I30) -> 0.02851711 | M30: COM | O30: =E30-'315805 - P0824'!F30 -> 0 | P30: =I30-'315805 - P0824'!J30 -> 0
A31: 29 | D31: 26116F - 2X6 116-5/8 HEM FIR STUD | E31: 526 | F31: 541 | G31: =+F31-E31 -> 15 | H31: =(F31-E31)/ABS(E31) -> 0.02851711 | I31: 628.84351 | J31: =(I31*H31)+I31 -> 646.77631 | K31: =J31-I31 -> 17.9328 | L31: =(J31-I31)/ABS(I31) -> 0.02851711 | M31: COM | O31: =E31-'315805 - P0824'!F31 -> 0 | P31: =I31-'315805 - P0824'!J31 -> 0
A32: 30 | D32: End of Studs | H32: =AVERAGE(H26:H31) -> 0.014977762 | L32: =AVERAGE(L26:L31) -> 0.014977762
A33: 31 | D33: Dimensional Lumber | M33: COM
A34: 32 | D34: 248F - 2X4X8 #2 AND BTR HEM FIR | E34: 540 | F34: 555 | G34: =+F34-E34 -> 15 | H34: =(F34-E34)/ABS(E34) -> 0.027777778 | I34: 614.01724 | J34: =(I34*H34)+I34 -> 631.07328 | K34: =J34-I34 -> 17.056034 | L34: =(J34-I34)/ABS(I34) -> 0.027777778 | M34: COM | O34: =E34-'315805 - P0824'!F34 -> 0 | P34: =I34-'315805 - P0824'!J34 -> 0
A35: 33 | D35: 2410F - 2X4X10 #2 AND BTR HEM FIR | E35: 540 | F35: =F34 -> 555 | G35: =+F35-E35 -> 15 | H35: =(F35-E35)/ABS(E35) -> 0.027777778 | I35: 614.01724 | J35: =(I35*H35)+I35 -> 631.07328 | K35: =J35-I35 -> 17.056034 | L35: =(J35-I35)/ABS(I35) -> 0.027777778 | M35: COM | O35: =E35-'315805 - P0824'!F35 -> 0 | P35: =I35-'315805 - P0824'!J35 -> 0
A36: 34 | D36: 2412F - 2X4X12 #2 AND BTR HEM FIR | E36: 540 | F36: =F34 -> 555 | G36: =+F36-E36 -> 15 | H36: =(F36-E36)/ABS(E36) -> 0.027777778 | I36: 614.01724 | J36: =(I36*H36)+I36 -> 631.07328 | K36: =J36-I36 -> 17.056034 | L36: =(J36-I36)/ABS(I36) -> 0.027777778 | M36: COM | O36: =E36-'315805 - P0824'!F36 -> 0 | P36: =I36-'315805 - P0824'!J36 -> 0
A37: 35 | D37: 2414F - 2X4X14 #2 AND BTR HEM FIR | E37: 540 | F37: =F34 -> 555 | G37: =+F37-E37 -> 15 | H37: =(F37-E37)/ABS(E37) -> 0.027777778 | I37: 614.01724 | J37: =(I37*H37)+I37 -> 631.07328 | K37: =J37-I37 -> 17.056034 | L37: =(J37-I37)/ABS(I37) -> 0.027777778 | M37: COM | O37: =E37-'315805 - P0824'!F37 -> 0 | P37: =I37-'315805 - P0824'!J37 -> 0
A38: 36 | D38: 2416F - 2X4X16 #2 AND BTR HEM FIR | E38: 540 | F38: =F34 -> 555 | G38: =+F38-E38 -> 15 | H38: =(F38-E38)/ABS(E38) -> 0.027777778 | I38: 614.01724 | J38: =(I38*H38)+I38 -> 631.07328 | K38: =J38-I38 -> 17.056034 | L38: =(J38-I38)/ABS(I38) -> 0.027777778 | M38: COM | O38: =E38-'315805 - P0824'!F38 -> 0 | P38: =I38-'315805 - P0824'!J38 -> 0
A39: 37 | D39: 2418F - 2X4X18 #2 AND BTR HEM FIR | E39: 540 | F39: =F34 -> 555 | G39: =+F39-E39 -> 15 | H39: =(F39-E39)/ABS(E39) -> 0.027777778 | I39: 614.01724 | J39: =(I39*H39)+I39 -> 631.07328 | K39: =J39-I39 -> 17.056034 | L39: =(J39-I39)/ABS(I39) -> 0.027777778 | M39: COM | O39: =E39-'315805 - P0824'!F39 -> 0 | P39: =I39-'315805 - P0824'!J39 -> 0
A40: 38 | D40: 2420F - 2X4X20 #2 AND BTR HEM FIR | E40: 540 | F40: =F34 -> 555 | G40: =+F40-E40 -> 15 | H40: =(F40-E40)/ABS(E40) -> 0.027777778 | I40: 614.01724 | J40: =(I40*H40)+I40 -> 631.07328 | K40: =J40-I40 -> 17.056034 | L40: =(J40-I40)/ABS(I40) -> 0.027777778 | M40: COM | O40: =E40-'315805 - P0824'!F40 -> 0 | P40: =I40-'315805 - P0824'!J40 -> 0
...

Sheet 315805 - P0824
E1: RANDOM LENGTH | F1: RANDOM LENGTH | I1: SELL PRICE | J1: SELL PRICE | M1: TYPE
B2: PROJECT | C2: SUPPLIER | D2: Product Code & Description | E2: P07 2024 JULY 06/14/24 | F2: P08 2024 AUGUST 07/12/24 | I2: P07 2024 JULY 06/14/24 | J2: P08 2024 AUGUST 07/12/24
A3: 1 | D3: Treated Materials | M3: COM
A4: 2 | C4: DH | D4: 2412BT - 2X4 12' Blue Borate Treated | E4: 696 | F4: 671 | G4: =+F4-E4 -> -25 | H4: =(F4-E4)/ABS(E4) -> -0.03591954 | I4: 839.55504 | J4: =(I4*H4)+I4 -> 809.39861 | K4: =J4-I4 -> -30.156431 | L4: =(J4-I4)/ABS(I4) -> -0.03591954 | M4: COM | O4: =E4-'315019 - P0724'!F4 -> 0 | P4: =I4-'315019 - P0724'!J4 -> 0
A5: 3 | D5: 2414BT - 2X4 14' Blue Borate Treated | E5: 696 | F5: =F4 -> 671 | G5: =+F5-E5 -> -25 | H5: =(F5-E5)/ABS(E5) -> -0.03591954 | I5: 839.55504 | J5: =(I5*H5)+I5 -> 809.39861 | K5: =J5-I5 -> -30.156431 | L5: =(J5-I5)/ABS(I5) -> -0.03591954 | M5: COM | O5: =E5-'315019 - P0724'!F5 -> 0 | P5: =I5-'315019 - P0724'!J5 -> 0
A6: 4 | D6: 2416BT - 2X4 16' Blue Borate Treated | E6: 696 | F6: =F4 -> 671 | G6: =+F6-E6 -> -25 | H6: =(F6-E6)/ABS(E6) -> -0.03591954 | I6: 839.55504 | J6: =(I6*H6)+I6 -> 809.39861 | K6: =J6-I6 -> -30.156431 | L6: =(J6-I6)/ABS(I6) -> -0.03591954 | M6: COM | O6: =E6-'315019 - P0724'!F6 -> 0 | P6: =I6-'315019 - P0724'!J6 -> 0
A7: 5 | C7: DH | D7: 2612BT - 2X6 12' Blue Borate Treated | E7: 656 | F7: 606 | G7: =+F7-E7 -> -50 | H7: =(F7-E7)/ABS(E7) -> -0.076219512 | I7: 846.79208 | J7: =(I7*H7)+I7 -> 782.25 | K7: =J7-I7 -> -64.542079 | L7: =(J7-I7)/ABS(I7) -> -0.076219512 | M7: COM | O7: =E7-'315019 - P0724'!F7 -> 0 | P7: =I7-'315019 - P0724'!J7 -> 0
A8: 6 | D8: 2614BT - 2X6 14' Blue Borate Treated | E8: 656 | F8: =F7 -> 606 | G8: =+F8-E8 -> -50 | H8: =(F8-E8)/ABS(E8) -> -0.076219512 | I8: 846.79208 | J8: =(I8*H8)+I8 -> 782.25 | K8: =J8-I8 -> -64.542079 | L8: =(J8-I8)/ABS(I8) -> -0.076219512 | M8: COM | O8: =E8-'315019 - P0724'!F8 -> 0 | P8: =I8-'315019 - P0724'!J8 -> 0
A9: 7 | D9: 2616BT - 2X6 16' Blue Borate Treated | E9: 656 | F9: =F7 -> 606 | G9: =+F9-E9 -> -50 | H9: =(F9-E9)/ABS(E9) -> -0.076219512 | I9: 846.79208 | J9: =(I9*H9)+I9 -> 782.25 | K9: =J9-I9 -> -64.542079 | L9: =(J9-I9)/ABS(I9) -> -0.076219512 | M9: COM | O9: =E9-'315019 - P0724'!F9 -> 0 | P9: =I9-'315019 - P0724'!J9 -> 0
A10: 8 | C10: DH | D10: 2412T - 2x4 12' #1 SYP Treated MCA Cedartone | E10: 800 | F10: 710 | G10: =+F10-E10 -> -90 | H10: =(F10-E10)/ABS(E10) -> -0.1125 | I10: 1062.4797 | J10: =(I10*H10)+I10 -> 942.95073 | K10: =J10-I10 -> -119.52897 | L10: =(J10-I10)/ABS(I10) -> -0.1125 | M10: COM | O10: =E10-'315019 - P0724'!F10 -> 0 | P10: =I10-'315019 - P0724'!J10 -> 0
A11: 9 | D11: 2416T - 2x4 16' #1 SYP Treated MCA Cedartone | E11: 800 | F11: =F10 -> 710 | G11: =+F11-E11 -> -90 | H11: =(F11-E11)/ABS(E11) -> -0.1125 | I11: 1062.4797 | J11: =(I11*H11)+I11 -> 942.95073 | K11: =J11-I11 -> -119.52897 | L11: =(J11-I11)/ABS(I11) -> -0.1125 | M11: COM | O11: =E11-'315019 - P0724'!F11 -> 0 | P11: =I11-'315019 - P0724'!J11 -> 0
A12: 10 | C12: DH | D12: 2612T - 2x6 12' #1 SYP Treated MCA Cedartone | E12: 725 | F12: 685 | G12: =+F12-E12 -> -40 | H12: =(F12-E12)/ABS(E12) -> -0.055172414 | I12: 864.81582 | J12: =(I12*H12)+I12 -> 817.10184 | K12: =J12-I12 -> -47.713976 | L12: =(J12-I12)/ABS(I12) -> -0.055172414 | M12: COM | O12: =E12-'315019 - P0724'!F12 -> 0 | P12: =I12-'315019 - P0724'!J12 -> 0
A13: 11 | D13: 2616T - 2x6 16' #1 SYP Treated MCA Cedartone | E13: 725 | F13: =F12 -> 685 | G13: =+F13-E13 -> -40 | H13: =(F13-E13)/ABS(E13) -> -0.055172414 | I13: 864.81582 | J13: =(I13*H13)+I13 -> 817.10184 | K13: =J13-I13 -> -47.713976 | L13: =(J13-I13)/ABS(I13) -> -0.055172414 | M13: COM | O13: =E13-'315019 - P0724'!F13 -> 0 | P13: =I13-'315019 - P0724'!J13 -> 0
A14: 12 | D14: 2812T - 2x8 12' #1 SYP Treated MCA Cedartone | E14: 700 | F14: 660 | G14: =+F14-E14 -> -40 | H14: =(F14-E14)/ABS(E14) -> -0.057142857 | I14: 899.79852 | J14: =(I14*H14)+I14 -> 848.38146 | K14: =J14-I14 -> -51.417058 | L14: =(J14-I14)/ABS(I14) -> -0.057142857 | M14: COM | O14: =E14-'315019 - P0724'!F14 -> 0 | P14: =I14-'315019 - P0724'!J14 -> 0
A15: 13 | D15: 2816T - 2x8 16' #1 SYP Treated MCA Cedartone | E15: 700 | F15: =F14 -> 660 | G15: =+F15-E15 -> -40 | H15: =(F15-E15)/ABS(E15) -> -0.057142857 | I15: 899.79852 | J15: =(I15*H15)+I15 -> 848.38146 | K15: =J15-I15 -> -51.417058 | L15: =(J15-I15)/ABS(I15) -> -0.057142857 | M15: COM | O15: =E15-'315019 - P0724'!F15 -> 0 | P15: =I15-'315019 - P0724'!J15 -> 0
A16: 14 | C16: DH | D16: 21012T - 2x10 12' #1 SYP Treated MCA Cedartone | E16: 790 | F16: 780 | G16: =+F16-E16 -> -10 | H16: =(F16-E16)/ABS(E16) -> -0.012658228 | I16: 1112.7957 | J16: =(I16*H16)+I16 -> 1098.7097 | K16: =J16-I16 -> -14.086022 | L16: =(J16-I16)/ABS(I16) -> -0.012658228 | M16: COM | O16: =E16-'315019 - P0724'!F16 -> 0 | P16: =I16-'315019 - P0724'!J16 -> 0
A17: 15 | D17: 21016T - 2x10 16' #1 SYP Treated MCA Cedartone | E17: 790 | F17: =F16 -> 780 | G17: =+F17-E17 -> -10 | H17: =(F17-E17)/ABS(E17) -> -0.012658228 | I17: 1112.7957 | J17: =(I17*H17)+I17 -> 1098.7097 | K17: =J17-I17 -> -14.086022 | L17: =(J17-I17)/ABS(I17) -> -0.012658228 | M17: COM | O17: =E17-'315019 - P0724'!F17 -> 0 | P17: =I17-'315019 - P0724'!J17 -> 0
A18: 16 | C18: DH | D18: 21212T - 2x12 12' #1 SYP Treated MCA Cedartone | E18: 850 | F18: 845 | G18: =+F18-E18 -> -5 | H18: =(F18-E18)/ABS(E18) -> -0.0058823529 | I18: 1181.3027 | J18: =(I18*H18)+I18 -> 1174.3539 | K18: =J18-I18 -> -6.9488397 | L18: =(J18-I18)/ABS(I18) -> -0.0058823529 | M18: COM | O18: =E18-'315019 - P0724'!F18 -> 0 | P18: =I18-'315019 - P0724'!J18 -> 0
A19: 17 | D19: 21216T - 2x12 16' #1 SYP Treated MCA Cedartone | E19: 850 | F19: =F18 -> 845 | G19: =+F19-E19 -> -5 | H19: =(F19-E19)/ABS(E19) -> -0.0058823529 | I19: 1181.3027 | J19: =(I19*H19)+I19 -> 1174.3539 | K19: =J19-I19 -> -6.9488397 | L19: =(J19-I19)/ABS(I19) -> -0.0058823529 | M19: COM | O19: =E19-'315019 - P0724'!F19 -> 0 | P19: =I19-'315019 - P0724'!J19 -> 0
A20: 18 | C20: DH | D20: 21220T - 2x12 20' #1 SYP Treated MCA Cedartone | E20: 1040 | F20: 1040 | G20: =+F20-E20 -> 0 | H20: =(F20-E20)/ABS(E20) -> 0 | I20: 2099.3185 | J20: =(I20*H20)+I20 -> 2099.3185 | K20: =J20-I20 -> 0 | L20: =(J20-I20)/ABS(I20) -> 0 | M20: COM | O20: =E20-'315019 - P0724'!F20 -> 998.2 | P20: =I20-'315019 - P0724'!J20 -> 0
A21: 19 | C21: DH | D21: 4410T - 4X4 10' HF Std/btr S4S CEDARTONE GROUND CONTACT | E21: 16.07 | F21: 16.07 | G21: =+F21-E21 -> 0 | H21: =(F21-E21)/ABS(E21) -> 0 | I21: 36.488665 | J21: =(I21*H21)+I21 -> 36.488665 | K21: =J21-I21 -> 0 | L21: =(J21-I21)/ABS(I21) -> 0 | M21: COM | O21: =E21-'315019 - P0724'!F21 -> 0 | P21: =I21-'315019 - P0724'!J21 -> 0
A22: 20 | C22: DH | D22: 6610T - 6X6 10' HF #2 S4S CEDARTONE GROUND CONTACT | E22: 1430 | F22: 1430 | G22: =+F22-E22 -> 0 | H22: =(F22-E22)/ABS(E22) -> 0 | I22: 2041.9222 | J22: =(I22*H22)+I22 -> 2041.9222 | K22: =J22-I22 -> 0 | L22: =(J22-I22)/ABS(I22) -> 0 | M22: COM | O22: =E22-'315019 - P0724'!F22 -> 0 | P22: =I22-'315019 - P0724'!J22 -> 0
A23: 21 | D23: 6612T - 6X6 12' HF #2 S4S CEDARTONE GROUND CONTACT | E23: 1430 | F23: =F22 -> 1430 | G23: =+F23-E23 -> 0 | H23: =(F23-E23)/ABS(E23) -> 0 | I23: 2041.9222 | J23: =(I23*H23)+I23 -> 2041.9222 | K23: =J23-I23 -> 0 | L23: =(J23-I23)/ABS(I23) -> 0 | M23: COM | O23: =E23-'315019 - P0724'!F23 -> 0 | P23: =I23-'315019 - P0724'!J23 -> 0
A24: 22 | D24: End of Treated Materials | H24: =AVERAGE(H4:H23) -> -0.041156443 | L24: =AVERAGE(L4:L23) -> -0.041156443
A25: 23 | D25: Studs | M25: COM
A26: 24 | D26: 2492F - 2X4 92-5/8 HEM FIR STUD | E26: 486 | F26: 441 | G26: =+F26-E26 -> -45 | H26: =(F26-E26)/ABS(E26) -> -0.092592593 | I26: 721.06173 | J26: =(I26*H26)+I26 -> 654.29675 | K26: =J26-I26 -> -66.764975 | L26: =(J26-I26)/ABS(I26) -> -0.092592593 | M26: COM | O26: =E26-'315019 - P0724'!F26 -> 0 | P26: =I26-'315019 - P0724'!J26 -> 0
A27: 25 | D27: 24104F - 2X4 104-5/8 HEM FIR STUD | E27: 506 | F27: 471 | G27: =+F27-E27 -> -35 | H27: =(F27-E27)/ABS(E27) -> -0.06916996 | I27: 667.52172 | J27: =(I27*H27)+I27 -> 621.34927 | K27: =J27-I27 -> -46.172451 | L27: =(J27-I27)/ABS(I27) -> -0.06916996 | M27: COM | O27: =E27-'315019 - P0724'!F27 -> 0 | P27: =I27-'315019 - P0724'!J27 -> 0
A28: 26 | D28: 24116F - 2X4 116-5/8 HEM FIR STUD | E28: 506 | F28: 471 | G28: =+F28-E28 -> -35 | H28: =(F28-E28)/ABS(E28) -> -0.06916996 | I28: 626.9158 | J28: =(I28*H28)+I28 -> 583.55206 | K28: =J28-I28 -> -43.363741 | L28: =(J28-I28)/ABS(I28) -> -0.06916996 | M28: COM | O28: =E28-'315019 - P0724'!F28 -> 0 | P28: =I28-'315019 - P0724'!J28 -> 0
A29: 27 | D29: 2692F - 2X6 92-5/8 HEM FIR STUD | E29: 451 | F29: 431 | G29: =+F29-E29 -> -20 | H29: =(F29-E29)/ABS(E29) -> -0.044345898 | I29: 579.75675 | J29: =(I29*H29)+I29 -> 554.04692 | K29: =J29-I29 -> -25.709834 | L29: =(J29-I29)/ABS(I29) -> -0.044345898 | M29: COM | O29: =E29-'315019 - P0724'!F29 -> 0 | P29: =I29-'315019 - P0724'!J29 -> 0
A30: 28 | D30: 26104F - 2X6 104-5/8 HEM FIR STUD | E30: 556 | F30: 526 | G30: =+F30-E30 -> -30 | H30: =(F30-E30)/ABS(E30) -> -0.053956835 | I30: 703.62404 | J30: =(I30*H30)+I30 -> 665.65872 | K30: =J30-I30 -> -37.965326 | L30: =(J30-I30)/ABS(I30) -> -0.053956835 | M30: COM | O30: =E30-'315019 - P0724'!F30 -> 0 | P30: =I30-'315019 - P0724'!J30 -> 0
A31: 29 | D31: 26116F - 2X6 116-5/8 HEM FIR STUD | E31: 556 | F31: 526 | G31: =+F31-E31 -> -30 | H31: =(F31-E31)/ABS(E31) -> -0.053956835 | I31: 664.70911 | J31: =(I31*H31)+I31 -> 628.84351 | K31: =J31-I31 -> -35.8656 | L31: =(J31-I31)/ABS(I31) -> -0.053956835 | M31: COM | O31: =E31-'315019 - P0724'!F31 -> 0 | P31: =I31-'315019 - P0724'!J31 -> 0
A32: 30 | D32: End of Studs | H32: =AVERAGE(H26:H31) -> -0.063865347 | L32: =AVERAGE(L26:L31) -> -0.063865347
A33: 31 | D33: Dimensional Lumber | M33: COM
A34: 32 | D34: 248F - 2X4X8 #2 AND BTR HEM FIR | E34: 565 | F34: 540 | G34: =+F34-E34 -> -25 | H34: =(F34-E34)/ABS(E34) -> -0.044247788 | I34: 642.44397 | J34: =(I34*H34)+I34 -> 614.01724 | K34: =J34-I34 -> -28.426724 | L34: =(J34-I34)/ABS(I34) -> -0.044247788 | M34: COM | O34: =E34-'315019 - P0724'!F34 -> 0 | P34: =I34-'315019 - P0724'!J34 -> 0
A35: 33 | D35: 2410F - 2X4X10 #2 AND BTR HEM FIR | E35: 565 | F35: =F34 -> 540 | G35: =+F35-E35 -> -25 | H35: =(F35-E35)/ABS(E35) -> -0.044247788 | I35: 642.44397 | J35: =(I35*H35)+I35 -> 614.01724 | K35: =J35-I35 -> -28.426724 | L35: =(J35-I35)/ABS(I35) -> -0.044247788 | M35: COM | O35: =E35-'315019 - P0724'!F35 -> 0 | P35: =I35-'315019 - P0724'!J35 -> 0
A36: 34 | D36: 2412F - 2X4X12 #2 AND BTR HEM FIR | E36: 565 | F36: =F34 -> 540 | G36: =+F36-E36 -> -25 | H36: =(F36-E36)/ABS(E36) -> -0.044247788 | I36: 642.44397 | J36: =(I36*H36)+I36 -> 614.01724 | K36: =J36-I36 -> -28.426724 | L36: =(J36-I36)/ABS(I36) -> -0.044247788 | M36: COM | O36: =E36-'315019 - P0724'!F36 -> 0 | P36: =I36-'315019 - P0724'!J36 -> 0
A37: 35 | D37: 2414F - 2X4X14 #2 AND BTR HEM FIR | E37: 565 | F37: =F34 -> 540 | G37: =+F37-E37 -> -25 | H37: =(F37-E37)/ABS(E37) -> -0.044247788 | I37: 642.44397 | J37: =(I37*H37)+I37 -> 614.01724 | K37: =J37-I37 -> -28.426724 | L37: =(J37-I37)/ABS(I37) -> -0.044247788 | M37: COM | O37: =E37-'315019 - P0724'!F37 -> 0 | P37: =I37-'315019 - P0724'!J37 -> 0
A38: 36 | D38: 2416F - 2X4X16 #2 AND BTR HEM FIR | E38: 565 | F38: =F34 -> 540 | G38: =+F38-E38 -> -25 | H38: =(F38-E38)/ABS(E38) -> -0.044247788 | I38: 642.44397 | J38: =(I38*H38)+I38 -> 614.01724 | K38: =J38-I38 -> -28.426724 | L38: =(J38-I38)/ABS(I38) -> -0.044247788 | M38: COM | O38: =E38-'315019 - P0724'!F38 -> 0 | P38: =I38-'315019 - P0724'!J38 -> 0
A39: 37 | D39: 2418F - 2X4X18 #2 AND BTR HEM FIR | E39: 565 | F39: =F34 -> 540 | G39: =+F39-E39 -> -25 | H39: =(F39-E39)/ABS(E39) -> -0.044247788 | I39: 642.44397 | J39: =(I39*H39)+I39 -> 614.01724 | K39: =J39-I39 -> -28.426724 | L39: =(J39-I39)/ABS(I39) -> -0.044247788 | M39: COM | O39: =E39-'315019 - P0724'!F39 -> 0 | P39: =I39-'315019 - P0724'!J39 -> 0
A40: 38 | D40: 2420F - 2X4X20 #2 AND BTR HEM FIR | E40: 565 | F40: =F34 -> 540 | G40: =+F40-E40 -> -25 | H40: =(F40-E40)/ABS(E40) -> -0.044247788 | I40: 642.44397 | J40: =(I40*H40)+I40 -> 614.01724 | K40: =J40-I40 -> -28.426724 | L40: =(J40-I40)/ABS(I40) -> -0.044247788 | M40: COM | O40: =E40-'315019 - P0724'!F40 -> 0 | P40: =I40-'315019 - P0724'!J40 -> 0
...

Sheet 315019 - P0724
E1: RANDOM LENGTH | F1: RANDOM LENGTH | I1: SELL PRICE | J1: SELL PRICE | M1: TYPE
B2: PROJECT | C2: SUPPLIER | D2: Product Code & Description | E2: P06 2024 JUNE 05/10/24 | F2: P07 2024 JULY 06/14/24 | I2: P06 2024 JUNE 05/10/24 | J2: P07 2024 JULY 06/14/24
A3: 1 | D3: Treated Materials | M3: COM
A4: 2 | C4: DH | D4: 2412BT - 2X4 12' Blue Borate Treated | E4: 681 | F4: 696 | G4: =+F4-E4 -> 15 | H4: =(F4-E4)/ABS(E4) -> 0.022026432 | I4: 821.46118 | J4: =(I4*H4)+I4 -> 839.55504 | K4: =J4-I4 -> 18.093859 | L4: =(J4-I4)/ABS(I4) -> 0.022026432 | M4: COM | O4: =E4-'314020 - P0624'!F4 -> 0 | P4: =I4-'314020 - P0624'!J4 -> 0
A5: 3 | D5: 2414BT - 2X4 14' Blue Borate Treated | E5: 681 | F5: =F4 -> 696 | G5: =+F5-E5 -> 15 | H5: =(F5-E5)/ABS(E5) -> 0.022026432 | I5: 821.46118 | J5: =(I5*H5)+I5 -> 839.55504 | K5: =J5-I5 -> 18.093859 | L5: =(J5-I5)/ABS(I5) -> 0.022026432 | M5: COM | O5: =E5-'314020 - P0624'!F5 -> 0 | P5: =I5-'314020 - P0624'!J5 -> 0
A6: 4 | D6: 2416BT - 2X4 16' Blue Borate Treated | E6: 681 | F6: =F4 -> 696 | G6: =+F6-E6 -> 15 | H6: =(F6-E6)/ABS(E6) -> 0.022026432 | I6: 821.46118 | J6: =(I6*H6)+I6 -> 839.55504 | K6: =J6-I6 -> 18.093859 | L6: =(J6-I6)/ABS(I6) -> 0.022026432 | M6: COM | O6: =E6-'314020 - P0624'!F6 -> 0 | P6: =I6-'314020 - P0624'!J6 -> 0
A7: 5 | C7: DH | D7: 2612BT - 2X6 12' Blue Borate Treated | E7: 686 | F7: 656 | G7: =+F7-E7 -> -30 | H7: =(F7-E7)/ABS(E7) -> -0.043731778 | I7: 885.51733 | J7: =(I7*H7)+I7 -> 846.79208 | K7: =J7-I7 -> -38.725248 | L7: =(J7-I7)/ABS(I7) -> -0.043731778 | M7: COM | O7: =E7-'314020 - P0624'!F7 -> 0 | P7: =I7-'314020 - P0624'!J7 -> 0
A8: 6 | D8: 2614BT - 2X6 14' Blue Borate Treated | E8: 686 | F8: =F7 -> 656 | G8: =+F8-E8 -> -30 | H8: =(F8-E8)/ABS(E8) -> -0.043731778 | I8: 885.51733 | J8: =(I8*H8)+I8 -> 846.79208 | K8: =J8-I8 -> -38.725248 | L8: =(J8-I8)/ABS(I8) -> -0.043731778 | M8: COM | O8: =E8-'314020 - P0624'!F8 -> 0 | P8: =I8-'314020 - P0624'!J8 -> 0
